Workbook

Sheet Start_Here
A1: SEO recovery plan: audit and refresh model
A2: What this sheet tells you: how to read this workbook, in what order, and what the colors mean.
A4: Beat Claude challenge SEO Strategy 003, brief version 2026-07. Prepared by Qasim Khursheed, October 2026.
A5: Fixture: content_audit_sample.csv, SHA-256 fa691abc31b14093230657d17674ab0120449c54d20cef54bfe73686fe9b99c6
A7: Read in this order
A8: 1. Why_Traffic_Dropped: where the lost traffic went and what the data tested.
A9: 2. Page_Triage: every page in the fixture with its decision (Protect, Refresh, Consolidate, Kill), the rule behind it, priority, what we do and what to watch out for.
A10: 3. Triage_Rules: the eight rules in order. Change a threshold here if you disagree with it.
A11: 4. Topics: which topics bring conversions, so new content and links go there first.
A12: 5. Plan_90_Days: what happens each week, who owns it, what you can see at the end of it.
A13: 6. Roadmap_12_Months: the four quarters and the five 90-day indicators with what we do if they do not move.
A14: 7. Budget: the $15,000 a month split, and how many posts that buys.
... A25: 18 pages is the top of the site, not a fair sample. Conversions cover 90 days while traffic is monthly. The fixture does not say whether traffic is GA4 sessions or a tool estimate. There are no last-year conversions, so we cannot see how conversions moved when rankings moved.

Sheet Why_Traffic_Dropped
A1: Where the lost traffic went, and what the data says caused it
A2: What this sheet tells you: the sample's lost traffic split by cause, then the questions we tested on the data and what each one found, in plain words.
A4: Cause | B4: Lost traffic (sum of Page_Triage rows) | C4: Share | D4: Pages | E4: What it means | F4: Fix
A5: A. Dated URL expired | B5: =SUMIF(Page_Triage!$R$5:$R$22,"A. Dated URL expired*",Page_Triage!$H$5:$H$22) -> -12510 | C5: =B5/Page_Triage!$H$23 -> 0.35032204 | D5: per-diem-rates-2022, quarterly-tax-deadlines-2023 | E5: Two year-stamped URLs lost 12,510 visits between them. The year in the URL expired. This is not decay, competition or a penalty. | F5: Redirect to evergreen URLs. Refresh on a calendar. No other spend.
A6: B. Head term | B6: =SUMIF(Page_Triage!$R$5:$R$22,"B. Head term*",Page_Triage!$H$5:$H$22) -> -16500 | C6: =B6/Page_Triage!$H$23 -> 0.46205545 | D6: what-is-expense-management, expense-management-guide, business-expense-categories, corporate-card-vs-credit-card | E6: The three head terms and the cannibal lost 16,500. Live SERPs show an AI Overview above every result and competitors updated in 2026. Our pages were last touched 2023-11 to 2024-08. | F6: Refresh for depth and citation, merge the cannibal, accept a ceiling where the AI Overview sits.
A7: C. Off-core, outranked by aggregators / thin | B7: =SUMIF(Page_Triage!$R$5:$R$22,"C. Off-core, outranked by aggregators / thin*",Page_Triage!$H$5:$H$22) -> -3250 | C7: =B7/Page_Triage!$H$23 -> 0.091010921 | D7: accounting-software-list, bookkeeping-basics | E7: Bookkeeping and accounting software lists. Zero conversions, under 10 referring domains each. | F7: Remove. Not our battle.
A8: D. Stale rules content | B8: =SUMIF(Page_Triage!$R$5:$R$22,"D. Stale rules content*",Page_Triage!$H$5:$H$22) -> -2200 | C8: =B8/Page_Triage!$H$23 -> 0.061607393 | D8: mileage-reimbursement-guide | E8: Mileage rules changed; the page was last updated 2022-11. | F8: Refresh with the current rate in a block that can be quoted.
A9: E. SERP feature at stable rank | B9: =SUMIF(Page_Triage!$R$5:$R$22,"E. SERP feature at stable rank*",Page_Triage!$H$5:$H$22) -> -800 | C9: =B9/Page_Triage!$H$23 -> 0.022402688 | D9: receipt-scanning-app | E9: Held #5 and still lost 31%. The live SERP has an AI Overview and consumer cashback intent. | F9: Refresh for citation rather than rank. Accept lower traffic.
A10: F. High-intent compare page slipping | B10: =SUMIF(Page_Triage!$R$5:$R$22,"F. High-intent compare page slipping*",Page_Triage!$H$5:$H$22) -> -800 | C10: =B10/Page_Triage!$H$23 -> 0.022402688 | D10: vs-ramp | E10: Slid 6 to 11. Small traffic, 22% of all conversions. | F10: Rebuild first. Highest conversion lever on the site.
A11: G. Link asset drifting | B11: =SUMIF(Page_Triage!$R$5:$R$22,"G. Link asset drifting*",Page_Triage!$H$5:$H$22) -> -500 | C11: =B11/Page_Triage!$H$23 -> 0.01400168 | D11: expense-fraud-statistics | E11: 74 referring domains, statistics from 2023. | F11: Yearly stat refresh. Internal link source for the comparison pages.
A12: H. Stable | B12: =SUMIF(Page_Triage!$R$5:$R$22,"H. Stable*",Page_Triage!$H$5:$H$22) -> -500 | C12: =B12/Page_Triage!$H$23 -> 0.01400168 | D12: expense-report-template, what-is-an-invoice, vs-brex | E12: Within noise. | F12: Leave alone.
A13: I. Gainers | B13: =SUMIF(Page_Triage!$R$5:$R$22,"I. Gainers*",Page_Triage!$H$5:$H$22) -> 1350 | C13: =B13/Page_Triage!$H$23 -> -0.037804537 | D13: travel-expense-policy, what-is-spend-management, branded page | E13: Updated 2025-01, a new cluster, and branded demand. | F13: Build around them. Report the branded page separately.
A14: Check: adds up to | B14: =SUM(B5:B13) -> -35710 | C14: =SUM(C5:C13) -> 1
A16: Two kinds of drop. The head terms slid 2 to 5 positions: that is competition. Four pages fell 17 to 38 positions (per diem 5 to 29, tax deadlines 3 to 41, accounting list 10 to 34, bookkeeping 14 to 31): that is expiry and off-topic content, and links do not fix it.
A18: What we tested on the 18 pages
A19: Question | B19: Result (correlation, -1 to +1) | C19: Strength | D19: What it means | E19: Cross-check (Pearson, live formula on Page_Triage) | F19: Pair tested
A20: Did the pages that dropped lose conversions? | B20: -0.6 | C20: moderate and reliable | D20: Pages that fell furthest have the fewest conversions, but they are the dated and off-topic pages that never converted. There are no last-year conversions in the fixture, so we cannot measure conversion change from this file. Needs GA4 by landing page for both years. | E20: =CORREL(Page_Triage!E5:E22,Page_Triage!O5:O22) -> -0.35190128 | F20: positions lost vs conversions
A21: Do more referring domains mean a better position today? | B21: -0.77 | C21: strong and reliable | D21: Yes. More links, better current position. Authority sets the floor. | E21: =CORREL(Page_Triage!K5:K22,Page_Triage!D5:D22) -> -0.57444215 | F21: referring domains vs position now
A22: Did referring domains protect pages from falling? | B22: -0.38 | C22: weak, could be chance | D22: No. The four pages with 50+ referring domains (84, 74, 61, 52) all fell, and they fell the least (2 to 5 places). The two gainers have 26 and 11. Once page age is held constant, link counts add nothing (partial correlation -0.07; age with links held constant: 0.80). What this file cannot see: link quality, links lost during the year, or competitors out-building us. Quietly neutralized links would look like the same slow slide on the head terms. The week-one audit (new and lost by month, anchors, DR spread, manual actions report) settles it and decides the order of Q1. | E22: =CORREL(Page_Triage!K5:K22,Page_Triage!E5:E22) -> -0.37020729 | F22: referring domains vs positions lost
A23: Do referring domains bring conversions? | B23: 0.61 | C23: moderate and reliable | D23: Only through traffic. Against conversions per 1,000 visits the link is 0.40 and could be chance. The best converting pages (comparisons) have 17 to 19 referring domains. Intent converts, links do not. | E23: =CORREL(Page_Triage!K5:K22,Page_Triage!O5:O22) -> 0.22623343 | F23: referring domains vs conversions
A24: Does a better position mean more conversions? | B24: -0.78 | C24: strong and reliable | D24: Yes, through traffic. The exception is the comparison pages: #8 and #11 with 10 to 13 conversions per 1,000 visits. | E24: =CORREL(Page_Triage!D5:D22,Page_Triage!O5:O22) -> -0.47716741 | F24: position now vs conversions
A25: Did older pages fall further? | B25: 0.83 | C25: strong and reliable | D25: Strongest signal in the file. The older the last update, the bigger the fall. Pages that fell: 39 months since update on average. Pages that held: 21. Nothing in the sample updated since 2025-01. | E25: =CORREL(Page_Triage!N5:N22,Page_Triage!E5:E22) -> 0.70592779 | F25: months since update vs positions lost
A26: Did older pages lose more traffic? | B26: -0.79 | C26: strong and reliable | D26: Same story in traffic terms. | E26: =CORREL(Page_Triage!N5:N22,Page_Triage!I5:I22) -> -0.70534482 | F26: months since update vs traffic change %
A27: Does traffic predict conversions? | B27: 0.69 | C27: moderate and reliable | D27: Loosely. 2,900 visits on the invoice page produce 0. 1,100 on the Ramp comparison produce 44. Traffic is the wrong KPI. | E27: =CORREL(Page_Triage!G5:G22,Page_Triage!O5:O22) -> 0.32242556 | F27: traffic now vs conversions
A28: Method: Spearman rank correlation from scripts/analyze_fixture.py (included). A correlation of 1.0 is a perfect match, 0 is no relationship, negative means they move in opposite directions. With 18 pages, read these as direction and rough strength. 'Reliable' means a p-value under 0.05. Column E is a live Pearson cross-check that moves if you edit Page_Triage.
A30: Pages that fell vs pages that held
A31: Group | B31: Pages | C31: Conversions (90 days) | D31: Traffic now | E31: Average months since update
A32: Fell | B32: =COUNTIF(Page_Triage!E5:E22,">0") -> 13 | C32: =SUMIF(Page_Triage!E5:E22,">0",Page_Triage!O5:O22) -> 119 | D32: =SUMIF(Page_Triage!E5:E22,">0",Page_Triage!G5:G22) -> 22140 | E32: 39
A33: Held or gained | B33: =COUNTIF(Page_Triage!E5:E22,"<=0") -> 5 | C33: =SUMIF(Page_Triage!E5:E22,"<=0",Page_Triage!O5:O22) -> 81 | D33: =SUMIF(Page_Triage!E5:E22,"<=0",Page_Triage!G5:G22) -> 13950 | E33: 21
A34: Months since update is the median from the script.

Sheet Page_Triage
A1: Every page: what happened to it and what we do
A2: What this sheet tells you: one row per fixture page. Blue columns are the fixture. Black columns are worked out. The Decision, Rule, Priority, What we do and Watch out columns are the plan for that page.
A3: Today, for the page-age calculation | B3: 2026-07 | C3: [Assumed] the brief version date | E3: Site traffic now | F3: 85000 | G3: 12 months ago | H3: 140000 | I3: [Observed] brief
A4: URL | B4: Target keyword | C4: Position 12 months ago | D4: Position now | E4: Positions lost (+ means it fell) | F4: Traffic 12 months ago | G4: Traffic now (monthly) | H4: Traffic change | I4: Traffic change % | J4: Share of the sample's lost traffic | K4: Referring domains | L4: Published | M4: Last updated | N4: Months since last update | O4: Conversions (90 days) | P4: Conversions per 1,000 visits | Q4: Topic | R4: Why it dropped | S4: Decision | T4: Rule that fired | U4: Priority | V4: What we do | W4: Watch out | X4: Fixture note | Y4: Expected traffic at the new position (click curve) | Z4: Traffic change the rank move does not explain
A5: /blog/what-is-expense-management | B5: what is expense management | C5: 1 | D5: 4 | E5: =D5-C5 -> 3 | F5: 14100 | G5: 6200 | H5: =G5-F5 -> -7900 | I5: =IF(F5=0,0,H5/F5) -> -0.56028369 | J5: =IF($H$23=0,0,H5/$H$23) -> 0.22122655 | K5: 84 | L5: 2021 | M5: 2024-01 | N5: =(VALUE(LEFT($B$3,4))-VALUE(LEFT(M5,4)))*12+(VALUE(RIGHT($B$3,2))-VALUE(RIGHT(M5,2))) -> 30 | O5: 9 | P5: =IF(G5=0,0,1000*O5/(3*G5)) -> 0.48387097 | Q5: Expense management core | R5: B. Head term: fresher competitors + AI Overview / snippet | S5: Refresh | T5: R7 lost positions or older than 18 months on a core topic: full refresh, URL kept, intent and SERP format re-checked (link assets with 70+ RDs are never redirected) | U5: P1 | V5: Full refresh, 301 the cannibal guide into it, structure the definition for AI Overview citation, target NetSuite's and Ramp's 2026 depth. Expect a ceiling: the AI Overview now sits above #1. | W5: The note blames a lost snippet to Ramp. The live SERP (Oct 2026) shows an AI Overview above every result, NetSuite at #1 and Ramp at #3. Recovery to #1 does not return 14,100 visits. | X5: Lost featured snippet to Ramp | Y5: =ROUND(F5*INDEX(Ref_CTR_Curve!$B$5:$B$45,MATCH(D5,Ref_CTR_Curve!$A$5:$A$45,0))/INDEX(Ref_CTR_Curve!$B$5:$B$45,MATCH(C5,Ref_CTR_Curve!$A$5:$A$45,0)),0) -> 2551 | Z5: =G5-Y5 -> 3649
A6: /blog/expense-management-guide | B6: what is expense management | C6: 12 | D6: 18 | E6: =D6-C6 -> 6 | F6: 900 | G6: 400 | H6: =G6-F6 -> -500 | I6: =IF(F6=0,0,H6/F6) -> -0.55555556 | J6: =IF($H$23=0,0,H6/$H$23) -> 0.01400168 | K6: 6 | L6: 2023 | M6: 2023-06 | N6: =(VALUE(LEFT($B$3,4))-VALUE(LEFT(M6,4)))*12+(VALUE(RIGHT($B$3,2))-VALUE(RIGHT(M6,2))) -> 37 | O6: 0 | P6: =IF(G6=0,0,1000*O6/(3*G6)) -> 0 | Q6: Expense management core | R6: B. Head term: fresher competitors + AI Overview / snippet (cannibal) | S6: Consolidate | T6: R1 same target keyword as a stronger URL (cannibal): 301 into the stronger URL | U6: P1 | V6: 301 to /blog/what-is-expense-management, merge any unique sections first. | W6: Cannibal of the page above. Its drop is not a separate problem. | X6: Second page targeting same keyword as above | Y6: =ROUND(F6*INDEX(Ref_CTR_Curve!$B$5:$B$45,MATCH(D6,Ref_CTR_Curve!$A$5:$A$45,0))/INDEX(Ref_CTR_Curve!$B$5:$B$45,MATCH(C6,Ref_CTR_Curve!$A$5:$A$45,0)),0) -> 565 | Z6: =G6-Y6 -> -165
A7: /blog/business-expense-categories | B7: business expense categories | C7: 2 | D7: 7 | E7: =D7-C7 -> 5 | F7: 9200 | G7: 3800 | H7: =G7-F7 -> -5400 | I7: =IF(F7=0,0,H7/F7) -> -0.58695652 | J7: =IF($H$23=0,0,H7/$H$23) -> 0.15121815 | K7: 52 | L7: 2020 | M7: 2023-11 | N7: =(VALUE(LEFT($B$3,4))-VALUE(LEFT(M7,4)))*12+(VALUE(RIGHT($B$3,2))-VALUE(RIGHT(M7,2))) -> 32 | O7: 4 | P7: =IF(G7=0,0,1000*O7/(3*G7)) -> 0.35087719 | Q7: Expense management core | R7: B. Head term: fresher competitors + AI Overview / snippet | S7: Refresh | T7: R7 lost positions or older than 18 months on a core topic: full refresh, URL kept, intent and SERP format re-checked (link assets with 70+ RDs are never redirected) | U7: P2 | V7: Refresh with current IRS category references, add a downloadable categories sheet (the SERP shows PDF and spreadsheet demand), link to the expense policy template. | X7: Outdated IRS category references | Y7: =ROUND(F7*INDEX(Ref_CTR_Curve!$B$5:$B$45,MATCH(D7,Ref_CTR_Curve!$A$5:$A$45,0))/INDEX(Ref_CTR_Curve!$B$5:$B$45,MATCH(C7,Ref_CTR_Curve!$A$5:$A$45,0)),0) -> 1476 | Z7: =G7-Y7 -> 2324
A8: /blog/corporate-card-vs-credit-card | B8: corporate card vs credit card | C8: 3 | D8: 5 | E8: =D8-C8 -> 2 | F8: 6800 | G8: 4100 | H8: =G8-F8 -> -2700 | I8: =IF(F8=0,0,H8/F8) -> -0.39705882 | J8: =IF($H$23=0,0,H8/$H$23) -> 0.075609073 | K8: 61 | L8: 2021 | M8: 2024-08 | N8: =(VALUE(LEFT($B$3,4))-VALUE(LEFT(M8,4)))*12+(VALUE(RIGHT($B$3,2))-VALUE(RIGHT(M8,2))) -> 23 | O8: 31 | P8: =IF(G8=0,0,1000*O8/(3*G8)) -> 2.5203252 | Q8: Corporate cards | R8: B. Head term: fresher competitors + AI Overview / snippet | S8: Protect | T8: R4 conversion asset (2+ conversions per 1k visits) or branded: URL untouched, light update, stronger CTA, internal links in | U8: P2 | V8: Light update plus CTA. Do not chase #1: the live SERP is JPMorgan, Chase, Reddit, Amex and Investopedia. Protect the 31 conversions. | W8: Note says highest converting blog page. The branded page in /blog has 52 conversions, this has 31. The notes are not reliable. | X8: Highest converting blog page | Y8: =ROUND(F8*INDEX(Ref_CTR_Curve!$B$5:$B$45,MATCH(D8,Ref_CTR_Curve!$A$5:$A$45,0))/INDEX(Ref_CTR_Curve!$B$5:$B$45,MATCH(C8,Ref_CTR_Curve!$A$5:$A$45,0)),0) -> 3400 | Z8: =G8-Y8 -> 700
A9: /blog/expense-report-template | B9: expense report template | C9: 4 | D9: 4 | E9: =D9-C9 -> 0 | F9: 5400 | G9: 5200 | H9: =G9-F9 -> -200 | I9: =IF(F9=0,0,H9/F9) -> -0.037037037 | J9: =IF($H$23=0,0,H9/$H$23) -> 0.0056006721 | K9: 38 | L9: 2022 | M9: 2024-10 | N9: =(VALUE(LEFT($B$3,4))-VALUE(LEFT(M9,4)))*12+(VALUE(RIGHT($B$3,2))-VALUE(RIGHT(M9,2))) -> 21 | O9: 12 | P9: =IF(G9=0,0,1000*O9/(3*G9)) -> 0.76923077 | Q9: Expense management core | R9: H. Stable (noise) | S9: Protect | T9: R5 holding or gaining and updated within 24 months: leave alone, extend the cluster around it | U9: P2 | V9: Leave the page, test the download-to-signup step. Confirm whether a download counts as a conversion before reporting it. | W9: Note says downloads drive signups. Is a download a conversion in the 12 count? Definition check before use. | X9: Stable; template download drives signups | Y9: =ROUND(F9*INDEX(Ref_CTR_Curve!$B$5:$B$45,MATCH(D9,Ref_CTR_Curve!$A$5:$A$45,0))/INDEX(Ref_CTR_Curve!$B$5:$B$45,MATCH(C9,Ref_CTR_Curve!$A$5:$A$45,0)),0) -> 5400 | Z9: =G9-Y9 -> -200
A10: /blog/per-diem-rates-2022 | B10: per diem rates | C10: 5 | D10: 29 | E10: =D10-C10 -> 24 | F10: 7800 | G10: 300 | H10: =G10-F10 -> -7500 | I10: =IF(F10=0,0,H10/F10) -> -0.96153846 | J10: =IF($H$23=0,0,H10/$H$23) -> 0.2100252 | K10: 22 | L10: 2022 | M10: 2022-03 | N10: =(VALUE(LEFT($B$3,4))-VALUE(LEFT(M10,4)))*12+(VALUE(RIGHT($B$3,2))-VALUE(RIGHT(M10,2))) -> 52 | O10: 0 | P10: =IF(G10=0,0,1000*O10/(3*G10)) -> 0 | Q10: Rates and deadlines (compliance utility) | R10: A. Dated URL expired | S10: Consolidate | T10: R2 year-stamped URL: 301 to an evergreen slug, refresh once a year, no further investment | U10: P1 | V10: 301 to /blog/per-diem-rates (evergreen), refresh each October when GSA publishes. Government sites own this SERP, so no further spend. | W10: Dated URL. Its loss is expiry, not decay, competition or a penalty. A refresh on this slug is wasted. | X10: Rates are 4 years stale; YMYL-adjacent | Y10: =ROUND(F10*INDEX(Ref_CTR_Curve!$B$5:$B$45,MATCH(D10,Ref_CTR_Curve!$A$5:$A$45,0))/INDEX(Ref_CTR_Curve!$B$5:$B$45,MATCH(C10,Ref_CTR_Curve!$A$5:$A$45,0)),0) -> 459 | Z10: =G10-Y10 -> -159
A11: /blog/what-is-an-invoice | B11: what is an invoice | C11: 8 | D11: 9 | E11: =D11-C11 -> 1 | F11: 3100 | G11: 2900 | H11: =G11-F11 -> -200 | I11: =IF(F11=0,0,H11/F11) -> -0.064516129 | J11: =IF($H$23=0,0,H11/$H$23) -> 0.0056006721 | K11: 15 | L11: 2020 | M11: 2023-02 | N11: =(VALUE(LEFT($B$3,4))-VALUE(LEFT(M11,4)))*12+(VALUE(RIGHT($B$3,2))-VALUE(RIGHT(M11,2))) -> 41 | O11: 0 | P11: =IF(G11=0,0,1000*O11/(3*G11)) -> 0 | Q11: Off-core finance education | R11: H. Stable (noise) | S11: Protect | T11: R6 traffic with zero product relevance: keep, no investment, test one product CTA, never report it as a win | U11: P3 | V11: No investment. One CTA test if the product has an invoice or AP feature; otherwise leave it. | W11: 2,900 visits and 0 conversions. Traffic-based triage would protect it as a win; conversion-based triage leaves it alone. | X11: High traffic; zero product relevance | Y11: =ROUND(F11*INDEX(Ref_CTR_Curve!$B$5:$B$45,MATCH(D11,Ref_CTR_Curve!$A$5:$A$45,0))/INDEX(Ref_CTR_Curve!$B$5:$B$45,MATCH(C11,Ref_CTR_Curve!$A$5:$A$45,0)),0) -> 2805 | Z11: =G11-Y11 -> 95
A12: /compare/vs-ramp | B12: expense management ramp alternative | C12: 6 | D12: 11 | E12: =D12-C12 -> 5 | F12: 1900 | G12: 1100 | H12: =G12-F12 -> -800 | I12: =IF(F12=0,0,H12/F12) -> -0.42105263 | J12: =IF($H$23=0,0,H12/$H$23) -> 0.022402688 | K12: 19 | L12: 2023 | M12: 2024-06 | N12: =(VALUE(LEFT($B$3,4))-VALUE(LEFT(M12,4)))*12+(VALUE(RIGHT($B$3,2))-VALUE(RIGHT(M12,2))) -> 25 | O12: 44 | P12: =IF(G12=0,0,1000*O12/(3*G12)) -> 13.333333 | Q12: Comparisons and alternatives | R12: F. High-intent compare page slipping | S12: Protect | T12: R4 conversion asset (2+ conversions per 1k visits) or branded: URL untouched, light update, stronger CTA, internal links in | U12: P1 | V12: Rebuild as a real comparison (pricing and feature table, honest tradeoffs), stronger CTA, internal links from the 84-RD and 74-RD blog pages. Highest conversion lever on the site. | W12: 44 conversions on 1,100 visits is 13 per 1k, 7x the blended rate. Check attribution (last click vs assisted) and branded mix before building the plan on this rate. | X12: Striking distance; highest intent page on site | Y12: =ROUND(F12*INDEX(Ref_CTR_Curve!$B$5:$B$45,MATCH(D12,Ref_CTR_Curve!$A$5:$A$45,0))/INDEX(Ref_CTR_Curve!$B$5:$B$45,MATCH(C12,Ref_CTR_Curve!$A$5:$A$45,0)),0) -> 518 | Z12: =G12-Y12 -> 582
A13: /compare/vs-brex | B13: expense management brex alternative | C13: 7 | D13: 8 | E13: =D13-C13 -> 1 | F13: 1000 | G13: 900 | H13: =G13-F13 -> -100 | I13: =IF(F13=0,0,H13/F13) -> -0.1 | J13: =IF($H$23=0,0,H13/$H$23) -> 0.002800336 | K13: 17 | L13: 2023 | M13: 2024-06 | N13: =(VALUE(LEFT($B$3,4))-VALUE(LEFT(M13,4)))*12+(VALUE(RIGHT($B$3,2))-VALUE(RIGHT(M13,2))) -> 25 | O13: 28 | P13: =IF(G13=0,0,1000*O13/(3*G13)) -> 10.37037 | Q13: Comparisons and alternatives | R13: H. Stable (noise) | S13: Protect | T13: R4 conversion asset (2+ conversions per 1k visits) or branded: URL untouched, light update, stronger CTA, internal links in | U13: P3 | V13: Keep, align format with the rebuilt vs-ramp page, add to the compare hub. | X13: Holding steady | Y13: =ROUND(F13*INDEX(Ref_CTR_Curve!$B$5:$B$45,MATCH(D13,Ref_CTR_Curve!$A$5:$A$45,0))/INDEX(Ref_CTR_Curve!$B$5:$B$45,MATCH(C13,Ref_CTR_Curve!$A$5:$A$45,0)),0) -> 700 | Z13: =G13-Y13 -> 200
A14: /blog/travel-expense-policy | B14: travel expense policy template | C14: 9 | D14: 6 | E14: =D14-C14 -> -3 | F14: 1700 | G14: 2400 | H14: =G14-F14 -> 700 | I14: =IF(F14=0,0,H14/F14) -> 0.41176471 | J14: =IF($H$23=0,0,H14/$H$23) -> -0.019602352 | K14: 26 | L14: 2022 | M14: 2025-01 | N14: =(VALUE(LEFT($B$3,4))-VALUE(LEFT(M14,4)))*12+(VALUE(RIGHT($B$3,2))-VALUE(RIGHT(M14,2))) -> 18 | O14: 8 | P14: =IF(G14=0,0,1000*O14/(3*G14)) -> 1.1111111 | Q14: Expense management core | R14: I. Gainers (recently updated / new cluster / branded) | S14: Protect | T14: R5 holding or gaining and updated within 24 months: leave alone, extend the cluster around it | U14: P3 | V14: Leave the page, add the policy template download and a CTA. Build the sibling policy pages around it. | W14: Rank improved 9 to 6 but traffic rose less than the CTR curve predicts. Likely a SERP feature capping clicks. | X14: One of few pages that improved | Y14: =ROUND(F14*INDEX(Ref_CTR_Curve!$B$5:$B$45,MATCH(D14,Ref_CTR_Curve!$A$5:$A$45,0))/INDEX(Ref_CTR_Curve!$B$5:$B$45,MATCH(C14,Ref_CTR_Curve!$A$5:$A$45,0)),0) -> 3937 | Z14: =G14-Y14 -> -1537
A15: /blog/company-name-expense-software | B15: company brand expense software | C15: 1 | D15: 1 | E15: =D15-C15 -> 0 | F15: 3600 | G15: 3900 | H15: =G15-F15 -> 300 | I15: =IF(F15=0,0,H15/F15) -> 0.083333333 | J15: =IF($H$23=0,0,H15/$H$23) -> -0.0084010081 | K15: 45 | L15: 2021 | M15: 2024-05 | N15: =(VALUE(LEFT($B$3,4))-VALUE(LEFT(M15,4)))*12+(VALUE(RIGHT($B$3,2))-VALUE(RIGHT(M15,2))) -> 26 | O15: 52 | P15: =IF(G15=0,0,1000*O15/(3*G15)) -> 4.4444444 | Q15: Branded | R15: I. Gainers (recently updated / new cluster / branded) | S15: Protect | T15: R4 conversion asset (2+ conversions per 1k visits) or branded: URL untouched, light update, stronger CTA, internal links in | U15: P3 | V15: Move out of blog reporting. Branded demand rather than SEO performance. | W15: Branded query filed under /blog. Inflates blog traffic and conversions. Exclude from the SEO baseline. | X15: Branded query; inflates blog totals | Y15: =ROUND(F15*INDEX(Ref_CTR_Curve!$B$5:$B$45,MATCH(D15,Ref_CTR_Curve!$A$5:$A$45,0))/INDEX(Ref_CTR_Curve!$B$5:$B$45,MATCH(C15,Ref_CTR_Curve!$A$5:$A$45,0)),0) -> 3600 | Z15: =G15-Y15 -> 300
A16: /blog/bookkeeping-basics | B16: bookkeeping basics | C16: 14 | D16: 31 | E16: =D16-C16 -> 17 | F16: 1400 | G16: 200 | H16: =G16-F16 -> -1200 | I16: =IF(F16=0,0,H16/F16) -> -0.85714286 | J16: =IF($H$23=0,0,H16/$H$23) -> 0.033604032 | K16: 4 | L16: 2020 | M16: 2020-09 | N16: =(VALUE(LEFT($B$3,4))-VALUE(LEFT(M16,4)))*12+(VALUE(RIGHT($B$3,2))-VALUE(RIGHT(M16,2))) -> 70 | O16: 0 | P16: =IF(G16=0,0,1000*O16/(3*G16)) -> 0 | Q16: Off-core finance education | R16: C. Off-core, outranked by aggregators / thin | S16: Kill | T16: R3 off-core topic, 0 conversions, under 10 RDs, lost over 15 positions: 410, or 301 to the nearest hub if any RDs are worth keeping | U16: P1 | V16: 410, or 301 to the expense categories page if the 4 RDs are real sites. | X16: Thin 600-word post; off-topic | Y16: =ROUND(F16*INDEX(Ref_CTR_Curve!$B$5:$B$45,MATCH(D16,Ref_CTR_Curve!$A$5:$A$45,0))/INDEX(Ref_CTR_Curve!$B$5:$B$45,MATCH(C16,Ref_CTR_Curve!$A$5:$A$45,0)),0) -> 212 | Z16: =G16-Y16 -> -12
A17: /blog/accounting-software-list | B17: best accounting software | C17: 10 | D17: 34 | E17: =D17-C17 -> 24 | F17: 2200 | G17: 150 | H17: =G17-F17 -> -2050 | I17: =IF(F17=0,0,H17/F17) -> -0.93181818 | J17: =IF($H$23=0,0,H17/$H$23) -> 0.057406889 | K17: 8 | L17: 2021 | M17: 2021-05 | N17: =(VALUE(LEFT($B$3,4))-VALUE(LEFT(M17,4)))*12+(VALUE(RIGHT($B$3,2))-VALUE(RIGHT(M17,2))) -> 62 | O17: 0 | P17: =IF(G17=0,0,1000*O17/(3*G17)) -> 0 | Q17: Off-core finance education | R17: C. Off-core, outranked by aggregators / thin | S17: Kill | T17: R3 off-core topic, 0 conversions, under 10 RDs, lost over 15 positions: 410, or 301 to the nearest hub if any RDs are worth keeping | U17: P1 | V17: Remove. The SERP belongs to aggregators and we have 0 conversions and 8 RDs. Redirect to the compare hub only if RDs are real. | W17: Outranked by aggregators. Not a content quality problem we can refresh our way out of. | X17: Listicle outranked by aggregators | Y17: =ROUND(F17*INDEX(Ref_CTR_Curve!$B$5:$B$45,MATCH(D17,Ref_CTR_Curve!$A$5:$A$45,0))/INDEX(Ref_CTR_Curve!$B$5:$B$45,MATCH(C17,Ref_CTR_Curve!$A$5:$A$45,0)),0) -> 206 | Z17: =G17-Y17 -> -56
A18: /blog/receipt-scanning-app | B18: receipt scanning app | C18: 5 | D18: 5 | E18: =D18-C18 -> 0 | F18: 2600 | G18: 1800 | H18: =G18-F18 -> -800 | I18: =IF(F18=0,0,H18/F18) -> -0.30769231 | J18: =IF($H$23=0,0,H18/$H$23) -> 0.022402688 | K18: 29 | L18: 2022 | M18: 2024-03 | N18: =(VALUE(LEFT($B$3,4))-VALUE(LEFT(M18,4)))*12+(VALUE(RIGHT($B$3,2))-VALUE(RIGHT(M18,2))) -> 28 | O18: 6 | P18: =IF(G18=0,0,1000*O18/(3*G18)) -> 1.1111111 | Q18: Expense management core | R18: E. SERP feature at stable rank (AI Overview, mixed intent) | S18: Refresh | T18: R7 lost positions or older than 18 months on a core topic: full refresh, URL kept, intent and SERP format re-checked (link assets with 70+ RDs are never redirected) | U18: P3 | V18: Refresh for citation rather than rank: the SERP has an AI Overview and mixed consumer intent. Short cited answer block, product angle, accept lower traffic. | W18: Position unchanged, traffic down 31%. A refresh aimed at rank cannot fix a click-share loss. The live SERP has an AI Overview and consumer cashback apps. | X18: Position stable; traffic fell after AI Overview appeared on SERP | Y18: =ROUND(F18*INDEX(Ref_CTR_Curve!$B$5:$B$45,MATCH(D18,Ref_CTR_Curve!$A$5:$A$45,0))/INDEX(Ref_CTR_Curve!$B$5:$B$45,MATCH(C18,Ref_CTR_Curve!$A$5:$A$45,0)),0) -> 2600 | Z18: =G18-Y18 -> -800
A19: /blog/mileage-reimbursement-guide | B19: mileage reimbursement rules | C19: 6 | D19: 13 | E19: =D19-C19 -> 7 | F19: 2900 | G19: 700 | H19: =G19-F19 -> -2200 | I19: =IF(F19=0,0,H19/F19) -> -0.75862069 | J19: =IF($H$23=0,0,H19/$H$23) -> 0.061607393 | K19: 18 | L19: 2022 | M19: 2022-11 | N19: =(VALUE(LEFT($B$3,4))-VALUE(LEFT(M19,4)))*12+(VALUE(RIGHT($B$3,2))-VALUE(RIGHT(M19,2))) -> 44 | O19: 2 | P19: =IF(G19=0,0,1000*O19/(3*G19)) -> 0.95238095 | Q19: Rates and deadlines (compliance utility) | R19: D. Stale rules content | S19: Refresh | T19: R7 lost positions or older than 18 months on a core topic: full refresh, URL kept, intent and SERP format re-checked (link assets with 70+ RDs are never redirected) | U19: P2 | V19: Refresh with the current IRS mileage rate, make the rate block easy to cite, link to the expense policy template. | X19: Rules changed; needs update pass | Y19: =ROUND(F19*INDEX(Ref_CTR_Curve!$B$5:$B$45,MATCH(D19,Ref_CTR_Curve!$A$5:$A$45,0))/INDEX(Ref_CTR_Curve!$B$5:$B$45,MATCH(C19,Ref_CTR_Curve!$A$5:$A$45,0)),0) -> 699 | Z19: =G19-Y19 -> 1
A20: /blog/what-is-spend-management | B20: what is spend management | C20: 15 | D20: 11 | E20: =D20-C20 -> -4 | F20: 300 | G20: 650 | H20: =G20-F20 -> 350 | I20: =IF(F20=0,0,H20/F20) -> 1.1666667 | J20: =IF($H$23=0,0,H20/$H$23) -> -0.0098011761 | K20: 11 | L20: 2024 | M20: 2024-12 | N20: =(VALUE(LEFT($B$3,4))-VALUE(LEFT(M20,4)))*12+(VALUE(RIGHT($B$3,2))-VALUE(RIGHT(M20,2))) -> 19 | O20: 3 | P20: =IF(G20=0,0,1000*O20/(3*G20)) -> 1.5384615 | Q20: Expense management core | R20: I. Gainers (recently updated / new cluster / branded) | S20: Protect | T20: R5 holding or gaining and updated within 24 months: leave alone, extend the cluster around it | U20: P3 | V20: Extend the cluster (spend management policy, spend management vs expense management, software). Small base, so label gains carefully. | W20: Gaining, but from 300 to 650. Too small a base to call a trend. | X20: Newer cluster; gaining unaided | Y20: =ROUND(F20*INDEX(Ref_CTR_Curve!$B$5:$B$45,MATCH(D20,Ref_CTR_Curve!$A$5:$A$45,0))/INDEX(Ref_CTR_Curve!$B$5:$B$45,MATCH(C20,Ref_CTR_Curve!$A$5:$A$45,0)),0) -> 391 | Z20: =G20-Y20 -> 259
A21: /blog/expense-fraud-statistics | B21: expense fraud statistics | C21: 7 | D21: 10 | E21: =D21-C21 -> 3 | F21: 1800 | G21: 1300 | H21: =G21-F21 -> -500 | I21: =IF(F21=0,0,H21/F21) -> -0.27777778 | J21: =IF($H$23=0,0,H21/$H$23) -> 0.01400168 | K21: 74 | L21: 2021 | M21: 2023-04 | N21: =(VALUE(LEFT($B$3,4))-VALUE(LEFT(M21,4)))*12+(VALUE(RIGHT($B$3,2))-VALUE(RIGHT(M21,2))) -> 39 | O21: 1 | P21: =IF(G21=0,0,1000*O21/(3*G21)) -> 0.25641026 | Q21: Data and statistics (link assets) | R21: G. Link asset drifting (stale stats) | S21: Refresh | T21: R7 lost positions or older than 18 months on a core topic: full refresh, URL kept, intent and SERP format re-checked (link assets with 70+ RDs are never redirected) | U21: P3 | V21: Refresh the statistics yearly, keep the URL forever, use it as the internal link source for compare pages. Never judge it on conversions. | W21: 1 conversion in 90 days but 74 referring domains. Judged on conversions it looks like a kill. It is the blog's link asset. | X21: Strongest backlink magnet on the blog | Y21: =ROUND(F21*INDEX(Ref_CTR_Curve!$B$5:$B$45,MATCH(D21,Ref_CTR_Curve!$A$5:$A$45,0))/INDEX(Ref_CTR_Curve!$B$5:$B$45,MATCH(C21,Ref_CTR_Curve!$A$5:$A$45,0)),0) -> 960 | Z21: =G21-Y21 -> 340
A22: /blog/quarterly-tax-deadlines-2023 | B22: quarterly tax deadlines | C22: 3 | D22: 41 | E22: =D22-C22 -> 38 | F22: 5100 | G22: 90 | H22: =G22-F22 -> -5010 | I22: =IF(F22=0,0,H22/F22) -> -0.98235294 | J22: =IF($H$23=0,0,H22/$H$23) -> 0.14029684 | K22: 9 | L22: 2023 | M22: 2023-01 | N22: =(VALUE(LEFT($B$3,4))-VALUE(LEFT(M22,4)))*12+(VALUE(RIGHT($B$3,2))-VALUE(RIGHT(M22,2))) -> 42 | O22: 0 | P22: =IF(G22=0,0,1000*O22/(3*G22)) -> 0 | Q22: Rates and deadlines (compliance utility) | R22: A. Dated URL expired | S22: Consolidate | T22: R2 year-stamped URL: 301 to an evergreen slug, refresh once a year, no further investment | U22: P1 | V22: 301 to /blog/quarterly-tax-deadlines (evergreen), annual refresh only. Zero conversions historically, so lowest priority after the redirect. | W22: Dated URL still indexed. 5,100 visits a month at its peak with 0 conversions. Recovering it adds traffic and no revenue. | X22: Dead dated page still indexed | Y22: =ROUND(F22*INDEX(Ref_CTR_Curve!$B$5:$B$45,MATCH(D22,Ref_CTR_Curve!$A$5:$A$45,0))/INDEX(Ref_CTR_Curve!$B$5:$B$45,MATCH(C22,Ref_CTR_Curve!$A$5:$A$45,0)),0) -> 75 | Z22: =G22-Y22 -> 15
A23: TOTAL (18 pages) | F23: =SUM(F5:F22) -> 71800 | G23: =SUM(G5:G22) -> 36090 | H23: =SUM(H5:H22) -> -35710 | I23: =H23/F23 -> -0.49735376 | J23: =SUM(J5:J22) -> 1 | O23: =SUM(O5:O22) -> 200 | P23: =1000*O23/(3*G23) -> 1.8472338
A25: Quick checks
A26: Sample traffic change | B26: =I23 -> -0.49735376
A27: Site traffic change (brief) | B27: =(F3-H3)/H3 -> -0.39285714
A28: Sample share of site traffic now | B28: =G23/F3 -> 0.42458824
A29: Sample share of site traffic 12 months ago | B29: =F23/H3 -> 0.51285714
A30: Sample change without the branded page | B30: =(SUMIF(B5:B22,"<>company brand expense software",G5:G22)-SUMIF(B5:B22,"<>company brand expense software",F5:F22))/SUMIF(B5:B22,"<>company brand expense software",F5:F22) -> -0.52800587
A31: Pages marked Protect | B31: =COUNTIF(S5:S22,"Protect") -> 8
A32: Pages marked Refresh | B32: =COUNTIF(S5:S22,"Refresh") -> 5
A33: Pages marked Consolidate | B33: =COUNTIF(S5:S22,"Consolidate") -> 3
A34: Pages marked Kill | B34: =COUNTIF(S5:S22,"Kill") -> 2
A35: Conversions on the two comparison pages | B35: =SUMIF(A5:A22,"/compare/*",O5:O22) -> 72
A36: Share of conversions from the top 4 pages | B36: =(LARGE(O5:O22,1)+LARGE(O5:O22,2)+LARGE(O5:O22,3)+LARGE(O5:O22,4))/O23 -> 0.775
A37: Traffic lost on pages with zero conversions | B37: =SUMIF(O5:O22,0,H5:H22) -> -16460
A38: ...as a share of all lost traffic | B38: =SUMIF(O5:O22,0,H5:H22)/H23 -> 0.46093531
A40: The last two columns (Y and Z) are the click-curve check: Y is what last year's traffic should have become at the new position; Z is traffic now minus Y. A big negative Z means the page lost clicks for a reason other than rank (an AI Overview, a changed SERP). Only receipt-scanning-app shows that.

Sheet Triage_Rules
A1: The eight rules, in order
A2: What this sheet tells you: how each page gets its decision. The first rule that fits wins. Yellow cells are thresholds you can change.
A4: Order | B4: Rule | C4: Decision | D4: Threshold | E4: Value | F4: Why
A5: R1 | B5: Two pages target the same keyword (cannibal) | C5: Consolidate | F5: Two URLs splitting one query never both win. Merge the unique parts and redirect the weaker one.
A6: R2 | B6: The URL has a year in it | C6: Consolidate | F6: The URL expires with the year. Redirect to an evergreen URL and refresh on a calendar. Refreshing the dated URL is wasted.
A7: R3 | B7: Off-topic AND zero conversions AND few referring domains AND lost many positions | C7: Kill | D7: Max referring domains / min positions lost | E7: 10 / 15 | F7: No revenue, no links, no rank. Remove it, or redirect to the nearest hub only if the links are from real sites.
A8: R4 | B8: Conversion page: conversions per 1,000 visits at or above the threshold, or a branded query | C8: Protect | D8: Min conversions per 1,000 visits | E8: 2 | F8: These pages pay for the program. Keep the URL, light update, stronger CTA, point internal links at it.
A9: R5 | B9: Holding or gaining rank AND updated recently | C9: Protect | D9: Max months since update | E9: 24 | F9: Working pages are left alone. Build the cluster around them.
A10: R6 | B10: Traffic with no product relevance | C10: Protect | F10: Keep it, spend nothing, test one CTA. Never report it as a win.
A11: R7 | B11: Lost positions, or old, on a core topic | C11: Refresh | D11: Max months since update | E11: 18 | F11: Full refresh, same URL, check intent and SERP format again. Pages with 70+ referring domains are never redirected.
A12: R8 | B12: Anything else | C12: Protect | F12: Check monthly.
A14: Running this on all 400 posts: export URL, target keyword, position now and 12 months ago, Search Console clicks, referring domains, last-modified date and GA4 conversions. Paste into Page_Triage. Apply R1 to R8 in order. A person reviews every Kill and Consolidate before any redirect goes live.

Sheet Topics
A1: Which topics bring conversions
A2: What this sheet tells you: traffic and conversions grouped by topic, so new content and links go to the topics that convert first.
A4: Topic | B4: Pages | C4: Traffic now | D4: Traffic 12 months ago | E4: Change % | F4: Conversions (90 days) | G4: Conversions per 1,000 visits | H4: Referring domains | I4: Where it sits in the plan
A5: Comparisons and alternatives | B5: =COUNTIF(Page_Triage!$Q$5:$Q$22,A5) -> 2 | C5: =SUMIF(Page_Triage!$Q$5:$Q$22,A5,Page_Triage!$G$5:$G$22) -> 2000 | D5: =SUMIF(Page_Triage!$Q$5:$Q$22,A5,Page_Triage!$F$5:$F$22) -> 2900 | E5: =IF(D5=0,0,(C5-D5)/D5) -> -0.31034483 | F5: =SUMIF(Page_Triage!$Q$5:$Q$22,A5,Page_Triage!$O$5:$O$22) -> 72 | G5: =IF(C5=0,0,1000*F5/(3*C5)) -> 12 | H5: =SUMIF(Page_Triage!$Q$5:$Q$22,A5,Page_Triage!$K$5:$K$22) -> 36 | I5: Fight. First priority for conversion. Rebuild vs-ramp, align vs-brex, add 2 comparison pages and an alternatives page. Links and internal links point here.
A6: Corporate cards | B6: =COUNTIF(Page_Triage!$Q$5:$Q$22,A6) -> 1 | C6: =SUMIF(Page_Triage!$Q$5:$Q$22,A6,Page_Triage!$G$5:$G$22) -> 4100 | D6: =SUMIF(Page_Triage!$Q$5:$Q$22,A6,Page_Triage!$F$5:$F$22) -> 6800 | E6: =IF(D6=0,0,(C6-D6)/D6) -> -0.39705882 | F6: =SUMIF(Page_Triage!$Q$5:$Q$22,A6,Page_Triage!$O$5:$O$22) -> 31 | G6: =IF(C6=0,0,1000*F6/(3*C6)) -> 2.5203252 | H6: =SUMIF(Page_Triage!$Q$5:$Q$22,A6,Page_Triage!$K$5:$K$22) -> 61 | I6: Fight for conversions rather than rank. Banks own the SERP. Protect the page and build the card decision content around it.
A7: Expense management core | B7: =COUNTIF(Page_Triage!$Q$5:$Q$22,A7) -> 7 | C7: =SUMIF(Page_Triage!$Q$5:$Q$22,A7,Page_Triage!$G$5:$G$22) -> 20450 | D7: =SUMIF(Page_Triage!$Q$5:$Q$22,A7,Page_Triage!$F$5:$F$22) -> 34200 | E7: =IF(D7=0,0,(C7-D7)/D7) -> -0.40204678 | F7: =SUMIF(Page_Triage!$Q$5:$Q$22,A7,Page_Triage!$O$5:$O$22) -> 42 | G7: =IF(C7=0,0,1000*F7/(3*C7)) -> 0.68459658 | H7: =SUMIF(Page_Triage!$Q$5:$Q$22,A7,Page_Triage!$K$5:$K$22) -> 246 | I7: Fight on depth and freshness. The head terms, templates and policy pages. Refresh the fallen ones, extend the spend management cluster, put a template or tool on every page.
A8: Data and statistics (link assets) | B8: =COUNTIF(Page_Triage!$Q$5:$Q$22,A8) -> 1 | C8: =SUMIF(Page_Triage!$Q$5:$Q$22,A8,Page_Triage!$G$5:$G$22) -> 1300 | D8: =SUMIF(Page_Triage!$Q$5:$Q$22,A8,Page_Triage!$F$5:$F$22) -> 1800 | E8: =IF(D8=0,0,(C8-D8)/D8) -> -0.27777778 | F8: =SUMIF(Page_Triage!$Q$5:$Q$22,A8,Page_Triage!$O$5:$O$22) -> 1 | G8: =IF(C8=0,0,1000*F8/(3*C8)) -> 0.25641026 | H8: =SUMIF(Page_Triage!$Q$5:$Q$22,A8,Page_Triage!$K$5:$K$22) -> 74 | I8: Flank. One data study a quarter from anonymized product data. Yearly refresh of the fraud page. This is where links come from.
A9: Rates and deadlines (compliance utility) | B9: =COUNTIF(Page_Triage!$Q$5:$Q$22,A9) -> 3 | C9: =SUMIF(Page_Triage!$Q$5:$Q$22,A9,Page_Triage!$G$5:$G$22) -> 1090 | D9: =SUMIF(Page_Triage!$Q$5:$Q$22,A9,Page_Triage!$F$5:$F$22) -> 15800 | E9: =IF(D9=0,0,(C9-D9)/D9) -> -0.93101266 | F9: =SUMIF(Page_Triage!$Q$5:$Q$22,A9,Page_Triage!$O$5:$O$22) -> 2 | G9: =IF(C9=0,0,1000*F9/(3*C9)) -> 0.6116208 | H9: =SUMIF(Page_Triage!$Q$5:$Q$22,A9,Page_Triage!$K$5:$K$22) -> 49 | I9: Flank cheaply. Evergreen URLs, refresh on a calendar, no new investment. Government owns the rates SERPs.
A10: Off-core finance education | B10: =COUNTIF(Page_Triage!$Q$5:$Q$22,A10) -> 3 | C10: =SUMIF(Page_Triage!$Q$5:$Q$22,A10,Page_Triage!$G$5:$G$22) -> 3250 | D10: =SUMIF(Page_Triage!$Q$5:$Q$22,A10,Page_Triage!$F$5:$F$22) -> 6700 | E10: =IF(D10=0,0,(C10-D10)/D10) -> -0.51492537 | F10: =SUMIF(Page_Triage!$Q$5:$Q$22,A10,Page_Triage!$O$5:$O$22) -> 0 | G10: =IF(C10=0,0,1000*F10/(3*C10)) -> 0 | H10: =SUMIF(Page_Triage!$Q$5:$Q$22,A10,Page_Triage!$K$5:$K$22) -> 27 | I10: Concede. Kill the thin pages, leave the invoice page alone. Aggregators and accounting software own these SERPs.
A11: Branded | B11: =COUNTIF(Page_Triage!$Q$5:$Q$22,A11) -> 1 | C11: =SUMIF(Page_Triage!$Q$5:$Q$22,A11,Page_Triage!$G$5:$G$22) -> 3900 | D11: =SUMIF(Page_Triage!$Q$5:$Q$22,A11,Page_Triage!$F$5:$F$22) -> 3600 | E11: =IF(D11=0,0,(C11-D11)/D11) -> 0.083333333 | F11: =SUMIF(Page_Triage!$Q$5:$Q$22,A11,Page_Triage!$O$5:$O$22) -> 52 | G11: =IF(C11=0,0,1000*F11/(3*C11)) -> 4.4444444 | H11: =SUMIF(Page_Triage!$Q$5:$Q$22,A11,Page_Triage!$K$5:$K$22) -> 45 | I11: Report separately. This is branded demand.
A12: Check | B12: =SUM(B5:B11) -> 18 | C12: =SUM(C5:C11) -> 36090 | F12: =SUM(F5:F11) -> 200
A14: Two comparison pages with 2,000 visits produce 72 of the 200 conversions. Seven core expense management pages with 20,450 visits produce 42. Topic authority still matters (the core cluster carries 246 of the sample's referring domains), but the money is in comparisons, cards and templates. The missing piece is lead quality: 44 conversions on vs-ramp could be Ramp's own customers. Pipeline by landing page from the CRM decides the final order.

Sheet Plan_90_Days
A1: The first 90 days, week by week
A2: What this sheet tells you: what ships each week, who owns it, what you can look at when it is done, and what it depends on.
A4: Week | B4: What ships | C4: Owner | D4: What you can see when it is done | E4: Depends on
A5: 1 | B5: KPI conversation with the VP; all Data_To_Request items sent; rank tracking live; Page_Triage loaded with the fixture rules | C5: Head of SEO, SEO Specialist | D5: Agreed KPI definition; data requests logged; rank tracker screenshot | E5: VP availability
A6: 2 | B6: Search Console 16-month series lined up with the update calendar; link audit (new and lost by month, anchors, DR spread); branded page moved out of the SEO baseline | C6: SEO Specialist | D6: One-page diagnosis note: step change or slow slide, link problem yes or no | E6: Week 1 data
A7: 3 | B7: Redirect map for the two dated URLs and the cannibal; removal decisions for the two off-topic pages; a person reviews every Kill and Consolidate | C7: SEO Specialist, Content Manager | D7: Redirect map (old URL, new URL, reason, referring domains carried) | E7: Link audit (check the links on the kills)
A8: 3-4 | B8: vs-ramp rebuilt: pricing and feature table, honest tradeoffs, CTA; vs-brex aligned to the same format | C8: Content Manager, CRO contractor | D8: New page live; conversion tracking on the CTA verified | E8: Product marketing for pricing facts
A9: 3-5 | B9: what-is-expense-management refreshed for depth and AI Overview citation; cannibal merged and redirected | C9: Content Manager, freelancer | D9: Refreshed URL live; Search Console URL filter saved for the holdout | E9: Redirect map
A10: 4 | B10: Holdout chosen: 20 pages to refresh in weeks 5 to 12 and 20 similar pages left alone; the matching rule written down | C10: SEO Specialist | D10: Holdout list with the matching rule (similar traffic, position and age) | E10: Full 400-post export
A11: 5-8 | B11: P2 refreshes: business expense categories (plus downloadable sheet), mileage guide, corporate card light update and CTA, template page download-to-signup test; 4 new posts in the spend management cluster | C11: Content Manager, freelancers | D11: 8 refreshes and 4 new posts live; CTA test running | E11: Sprint 1 for the download flow (or a plugin fallback)
A12: 6-10 | B12: Sprint 1 ships: blog template speed, redirect map deployed, related-posts and in-content link module | C12: Engineering, WordPress contractor | D12: PageSpeed lab LCP under 2.5s on the blog template; redirects returning 301; link module live | E12: Engineering sprint slot
A13: 9-12 | B13: P3 refreshes (receipt scanning for citation, fraud statistics yearly update); internal links from the two strongest blog pages into the comparison hub; data study #1 scoped with product and legal | C13: Content Manager, SEO Specialist | D13: 8 more refreshes live; internal link map; data study brief | E13: Legal sign-off on anonymized spend data
A14: 12-13 | B14: 90-day review: the five indicators in Roadmap_12_Months against their targets; continue, pivot or re-diagnose using the pre-agreed rules | C14: Head of SEO, VP Marketing | D14: 90-day note with the indicator table and the decision | E14: 8 weeks of indexed refresh data
A16: Throughout: 4 new posts a month minimum (the brief's floor), a weekly rank and Search Console check, and a monthly note on which pages lost, which gained, what changed on theirs and what changed on ours. Weeks are indicative [Assumed]; the last column says what moves them.

Sheet Roadmap_12_Months
A1: The four quarters and the 90-day indicators
A2: What this sheet tells you: what ships each quarter, which engineering sprint it needs, the milestone, then the five numbers we watch at 90 days and what we do if each one does not move.
A4: Quarter | B4: Ships | C4: Engineering sprint (1 per quarter) | D4: Milestone | E4: Label
A5: Q1 (days 1 to 90) | B5: KPI reset with the VP; GA4 and CRM baseline by landing page; Search Console trend on the update calendar; link audit; P1 then P2 pages; 4 new posts a month in the spend management cluster; refresh holdout (20 refreshed vs 20 left alone). | C5: Sprint 1: blog template speed (hero image, fonts, lazy loading, caching), redirect map, related-posts and in-content link module. Cut: INP work, redesign, any framework change. | D5: vs-ramp back in the top 8. what-is-expense-management top 3. Refreshed pages beating the holdout on impressions within 8 weeks. Comparison page conversion rate up 25%. Blog LCP under 2.5s in lab. 24 refreshes, 3 consolidations, 2 removals live. | E5: [Estimated]
A6: Q2 (months 4 to 6) | B6: Rules run on all 400 posts. 8 refreshes a month, consolidations by cluster. Data study #1 with outreach. Comparison hub: vs-ramp, vs-brex, 2 new comparison pages, 1 alternatives page. Template library with download-to-signup. | C6: Sprint 2: comparison page template (tables, schema, CTA components), template download flow, sitemap and removal handling. | D6: 100+ posts actioned. Organic conversions +40% to +60% on the Q1 baseline. Traffic 100K to 110K. | E6: [Estimated]
A7: Q3 (months 7 to 9) | B7: Refresh pipeline at full pace. Data study #2. First hire decision (content strategist or editor) once the 6-month freeze ends, only if refresh throughput is the bottleneck. Spend management cluster complete. | C7: Sprint 3: internal linking automation from the strongest pages to the comparison and product pages, hub pages. | D7: 250+ posts actioned. Organic conversions about +80%. Traffic 110K to 120K. | E7: [Estimated]
A8: Q4 (months 10 to 12) | B8: All 400 posts actioned. Yearly refresh calendar for rate and deadline pages. Yearly stat refresh on the fraud page. Holdout results and conversion lift reported. | C8: Sprint 4: reserve for whatever the data says (field vitals, schema, the next template). | D8: Base case: organic conversions about 2x baseline, traffic about 117K (low about 101K, stretch about 136K). 140K sits above the stretch case: the AI Overview on the head terms and the two expired URLs cap what the old pages can return; anything above comes from new clusters and templates. | E8: [Estimated]
A10: The five 90-day indicators
A11: Indicator | B11: Where we read it | C11: Target by day 90 | D11: If it does not move | E11: Label
A12: Positions: what is expense management, business expense categories, corporate card vs credit card, vs-ramp | B12: Ahrefs rank tracker, weekly, US desktop and mobile | C12: +2 positions on the first two; vs-ramp top 8; corporate card holds #5 | D12: If the head terms do not move after 8 weeks indexed: the problem is format and authority, not freshness. Move Q2 refresh budget to the data study and change the page format (tools and templates over prose). | E12: [Estimated]
A13: Impressions and clicks on refreshed pages vs the untouched holdout | B13: Search Console, URL filter, 8-week window | C13: Refreshed group up 20%+ on impressions relative to the holdout | D13: If refreshed pages do not beat the holdout: stop the refresh program at 24 and re-diagnose from Search Console and the update calendar. | E13: [Estimated]
A14: Organic conversions on the comparison pages | B14: GA4 landing page plus CRM source | C14: +25% conversion rate on vs-ramp and vs-brex | D14: If the rebuilt page converts no better: the CTA and offer are the problem. Product marketing owns the offer; SEO stays on traffic. | E14: [Estimated]
A15: Index hygiene | B15: Search Console pages report, Ahrefs site audit | C15: Dated URLs redirected, cannibal merged, one URL per target keyword | D15: Binary. If not done it is a process failure, not a strategy failure. | E15: [Observed]
A16: Blog template LCP | B16: PageSpeed Insights lab, then CrUX field after 28 days | C16: Under 2.5s lab by day 60 | D16: If the contractor cannot get there on WordPress: escalate to the Q2 sprint; do not spend Q1 sprint time on it twice. | E16: [Benchmarked] Google's 2.5s threshold

Sheet Budget
A1: The $15,000 a month, and what it buys
A2: What this sheet tells you: the monthly split by line with the reasoning, and how many posts the budget covers in a year.
A4: Line | B4: Monthly $ | C4: Label | D4: Basis
A5: Tools (Ahrefs, Clearscope, rank tracking) | B5: 1000 | C5: [Assumed] | D5: Existing tool stack per the brief. Prices change, so confirm against invoices.
A6: New posts: 4 a month x $300 | B6: =4*300 -> 1200 | C6: [Observed] | D6: Brief: 4 posts a month minimum, 3 freelancers at $300 a post.
A7: Refreshes: 8 a month x $200 | B7: =8*200 -> 1600 | C7: [Assumed] | D7: A refresh at two-thirds of a new post. Confirm with the freelancers; a heavy rewrite is a $300 job.
A8: Digital PR and data study (freelancer retainer) | B8: 4000 | C8: [Assumed] | D8: One original data asset a quarter from anonymized, aggregated product data plus outreach. No paid links at any price.
A9: WordPress speed and template contractor | B9: 2500 | C9: [Assumed] | D9: Front-loaded in Q1 (speed, image pipeline, caching, related-posts module). Drops to maintenance by Q3; the saving moves to refreshes.
A10: CRO and design for the comparison pages | B10: 1500 | C10: [Assumed] | D10: Comparison tables, CTAs, template downloads. Mainly Q1 and Q2.
A11: Automation and AI tooling, misc | B11: 700 | C11: [Assumed] | D11: Triage sheet automation, rank alerts, brief generation.
A12: Reserve | B12: 2500 | C12: [Assumed] | D12: Held for the Q3 data study or a fix that cannot wait for the sprint.
A13: Total | B13: =SUM(B5:B12) -> 15000
A14: Budget cap (brief) | B14: 15000 | C14: [Observed]
A15: Headroom | B15: =B14-B13 -> 0
A17: What the budget buys in a year
A18: New posts | B18: =4*12 -> 48
A19: Refreshes | B19: =8*12 -> 96
A20: Consolidations and removals (SEO Specialist time, no freelancer cost) | B20: 80 | C20: [Estimated]
A21: Posts actioned in 12 months | B21: =B18+B19+B20 -> 224
A22: Ramp's publishing pace (brief): posts a year | B22: =50*2 -> 100 | C22: [Estimated] | D22: 50 posts in 6 months in the brief. We cannot match it on new posts (48 a year). Refreshes and consolidations are where our effort goes.

Sheet Targets_Month_12
A1: Month-12 targets: three scenarios
A2: What this sheet tells you: a labeled projection, not a forecast. Low, base and stretch cases side by side. Every yellow cell is an assumption you can change and the three results update.
A3: Caveat that applies to every row below: the head-term share of loss (46%) comes from an 18-page sample of the biggest pages, and the written answer says not to scale that sample to the site. This sheet does scale it, as a scenario input only, so the targets have a shape. Search Console data in week one replaces the scaled input with the real one.
A4: Assumption | B4: Low | C4: Base | D4: Stretch | E4: Label | F4: Where it comes from
A5: Where we start: organic traffic a month | B5: 85000 | C5: 85000 | D5: 85000 | E5: [Observed] | F5: Brief. Source not stated.
A6: Where we start: organic conversions a month (index) | B6: 100 | C6: 100 | D6: 100 | E6: [Assumed] | F6: Index = 100 so the VP can drop in the real GA4 or CRM number. The fixture shows 200 conversions in 90 days on 18 pages, about 67 a month, but that is a sample.
A7: Traffic the head-term pages lost across the site in 12 months | B7: 20000 | C7: 25000 | D7: 30000 | E7: [Assumed] | F7: Scenario input. Base takes the sample's 46% head-term share of a 55,000 site loss (140K to 85K). Low and stretch bracket it. Replace with Search Console page data.
A8: Share of that we can win back while an AI Overview sits above #1 | B8: 0.25 | C8: 0.4 | D8: 0.55 | E8: [Estimated] | F8: Ahrefs, February 2026, 300,000 keywords: 58% lower click rate for the top result when an AI Overview appears. Winning back rank returns under half the old clicks in the base case.
A9: Traffic lift on a refreshed non-head page, 6 months after the refresh | B9: 0.15 | C9: 0.3 | D9: 0.45 | E9: [Assumed] | F9: Placeholder until the Q1 holdout gives a measured number. Replace at day 90.
A10: Share of non-head traffic on pages that get refreshed this year | B10: 0.4 | C10: 0.45 | D10: 0.5 | E10: [Estimated] | F10: 96 refreshes plus consolidations against 400 posts, weighted to the top of the traffic curve.
A11: Share of today's traffic on the head-term pages | B11: 0.25 | C11: 0.25 | D11: 0.25 | E11: [Estimated] | F11: Blog is 70% of traffic; the head terms are its biggest pages. Replace with Search Console page data.
A12: Traffic won back by making the dated URLs evergreen (monthly, by month 12) | B12: 2000 | C12: 4000 | D12: 6000 | E12: [Estimated] | F12: Two URLs peaked at 12,900 combined. Government and IRS own both SERPs now.
A13: Traffic from new content by month 12 (48 new posts plus the comparison hub) | B13: 5000 | C13: 9000 | D13: 14000 | E13: [Estimated] | F13: Base is about 190 visits a post at month 12, in line with the spend management page's 650 at under a year old.
A14: Conversion lift from CTAs, the comparison hub and templates (multiplier on conversions per visit) | B14: 1.3 | C14: 1.6 | D14: 1.9 | E14: [Estimated] | F14: Comparison pages convert at 10 to 13 per 1,000 visits against a blended 1.85. Base moves a tenth of visits to that path and fixes CTAs on the top 6 pages.
A16: Month-12 projection
B17: Low | C17: Base | D17: Stretch | E17: Label
A18: Today's traffic (untouched pages assumed flat) | B18: =B5 -> 85000 | C18: =C5 -> 85000 | D18: =D5 -> 85000 | E18: [Observed]
A19: Head-term traffic won back (lost x share we can win back) | B19: =B7*B8 -> 5000 | C19: =C7*C8 -> 10000 | D19: =D7*D8 -> 16500 | E19: [Assumed]
A20: Lift on the refreshed non-head pages | B20: =B5*(1-B11)*B10*B9 -> 3825 | C20: =C5*(1-C11)*C10*C9 -> 8606.25 | D20: =D5*(1-D11)*D10*D9 -> 14343.75 | E20: [Estimated]
A21: Dated URLs made evergreen | B21: =B12 -> 2000 | C21: =C12 -> 4000 | D21: =D12 -> 6000 | E21: [Estimated]
A22: New content | B22: =B13 -> 5000 | C22: =C13 -> 9000 | D22: =D13 -> 14000 | E22: [Estimated]
A23: Projected organic traffic, month 12 | B23: =SUM(B18:B22) -> 100825 | C23: =SUM(C18:C22) -> 116606.25 | D23: =SUM(D18:D22) -> 135843.75 | E23: [Estimated]
A24: Target in the brief | C24: 140000 | E24: [Observed]
A25: Gap to 140K | B25: =$C$24-B23 -> 39175 | C25: =$C$24-C23 -> 23393.75 | D25: =$C$24-D23 -> 4156.25
A26: Projected organic conversions, month 12 (index, start = 100) | B26: =B6*(B23/B5)*B14 -> 154.20294 | C26: =C6*(C23/C5)*C14 -> 219.49412 | D26: =D6*(D23/D5)*D14 -> 303.65074 | E26: [Estimated]
A28: Reading: low about 101K, base about 117K, stretch about 136K. The brief's 140K sits above the stretch case, because the head-term pages sit under an AI Overview and the two expired URLs are government-owned queries now. Conversions land between about 1.5x and 3x, base about 2.2x, because the conversion path (comparison hub, templates, CTAs) is where the upside is. The base case is a scenario, not a promise: the Q1 holdout replaces the refresh lift, and week-one Search Console data replaces the scaled head-term loss.

Sheet Data_To_Request
A1: What we ask for in week one
A2: What this sheet tells you: the nine data pulls, who owns each, why it matters, and what changes in the plan if the data says something different.
A4: # | B4: Data | C4: Source | D4: Owner | E4: Why it matters | F4: What changes if it says something different
A5: 1 | B5: Search Console clicks, impressions and average position by page and by query, the full 16 months, weekly | C5: Search Console export or API | D5: SEO Specialist | E5: The only accurate record of clicks, and of rankings that bounced back. 90 days hides seasonality and update timing. | F5: If Search Console shows a different shape from the brief's numbers, the whole diagnosis is re-run on it before anything ships.
A6: 2 | B6: GA4 sessions and conversions by landing page, both 12-month periods, organic only | C6: GA4 explorations | D6: SEO Specialist | E6: Sets the real baseline and shows what conversions were before the decline. | F6: If conversions cannot be tied to landing pages, fix tracking first; no page-level KPI until then.
A7: 3 | B7: CRM stage by landing page and first-touch source (MQL, SQL, opportunity, closed-won) | C7: HubSpot or Salesforce report | D7: VP Marketing to unlock | E7: Lead quality. 44 conversions on vs-ramp may be Ramp customers browsing. | F7: Pages are re-weighted by pipeline rather than by raw conversions.
A8: 4 | B8: Ahrefs new and lost referring domains by month for the domain and the four fallen head pages; anchor text mix; DR spread | C8: Ahrefs Site Explorer | D8: SEO Specialist | E8: Tests the spam hypothesis and the timing of links. | F8: A spike before the drop, or exact-match anchors, moves the link audit ahead of refreshes and triggers a targeted disavow.
A9: 5 | B9: Last-modified and publish date for all 400 posts | C9: WordPress export | D9: Content Manager | E9: Freshness is the strongest signal in the fixture; this is the full-site version. | F9: If modified dates are missing: Wayback Machine for the top 100, publish date for the rest.
A10: 6 | B10: Google update calendar lined up with the weekly Search Console series | C10: Search Engine Journal update history | D10: SEO Specialist | E10: A step down in a core update means content quality; in a spam update, links; a slow slide, decay and competition. | F10: The order of Q1 work changes with the answer.
A11: 7 | B11: CrUX field data and PageSpeed lab data for the blog template, mobile and desktop | C11: PageSpeed Insights, CrUX | D11: WordPress contractor | E11: Sizes the Sprint 1 speed work and gives the before number. | F11: If field data already passes, Sprint 1 time moves to the redirect map and link module.
A12: 8 | B12: Rank tracking: head terms and comparison pages, US desktop and mobile, weekly | C12: Ahrefs rank tracker | D12: SEO Specialist | E12: The 90-day indicators need a weekly series from day one. | F12: None. This is the measurement.
A13: 9 | B13: What counts as a conversion, agreed in writing (demo request, signup, download?) | C13: VP Marketing | D13: VP Marketing | E13: The template page's 12 conversions may be downloads. The KPI needs one definition. | F13: Baseline numbers are restated under the agreed definition.

Sheet Live_SERPs
A1: Who ranks today for the fallen keywords
A2: What this sheet tells you: the live Google US results pulled on 12 October 2026 for five fixture keywords: who is in the top 10, when their page was last updated, and whether an AI Overview sits on top.
A4: Pulled on | B4: Keyword | C4: Location | D4: Device | E4: DataForSEO task id (for re-checking) | F4: AI Overview present | G4: AI Overview position | H4: Organic rank | I4: Domain | J4: URL | K4: Page date Google shows
A5: 2026-10-12 | B5: what is expense management | C5: United States | D5: desktop | E5: 10121541-2246-0139-0000-b9554cac62ef | F5: yes | G5: above organic #1 | H5: 1 | I5: www.netsuite.com | J5: https://www.netsuite.com/portal/resource/articles/financial-management/expense-management-guide.shtml | K5: 2025-07-21
A6: 2026-10-12 | B6: what is expense management | C6: United States | D6: desktop | E6: 10121541-2246-0139-0000-b9554cac62ef | F6: yes | G6: above organic #1 | H6: 2 | I6: www.medius.com | J6: https://www.medius.com/glossary/what-is-expense-management-software/
A7: 2026-10-12 | B7: what is expense management | C7: United States | D7: desktop | E7: 10121541-2246-0139-0000-b9554cac62ef | F7: yes | G7: above organic #1 | H7: 3 | I7: ramp.com | J7: https://ramp.com/blog/what-is-expense-management | K7: 2026-07-22
A8: 2026-10-12 | B8: what is expense management | C8: United States | D8: desktop | E8: 10121541-2246-0139-0000-b9554cac62ef | F8: yes | G8: above organic #1 | H8: 4 | I8: www.airwallex.com | J8: https://www.airwallex.com/en-us/blog/what-is-expense-management | K8: 2026-05-31
